Workbook

Sheet Instructions
A1: Hackles Implementation Tracker [EXAMPLE DATA: made up]
A2: © 2026 Competence Collective. Lesson text and teaching materials CC BY-NC 4.0. The Hackles name, logos, characters and artwork are not covered by that license: print and share them unaltered for classroom and family use; any other use needs written permission. [VERIFY with counsel]
A3: Draft tool, 2026-10-05. Not legal advice. Hackles has not been reviewed, approved or endorsed by any state agency. Counts only: never type a student name, ID, initials or any detail that could identify a child.
A5: What this workbook does
A6: It tracks, for each class or group, which lessons were delivered, how many Help Ladder practice sessions ran, optional pre and post survey tallies, sensitive-lesson notices and opt-out counts, and family reply counts. The Summary and Dashboard roll these up by grade band. It never asks for, and has no space for, a student name, ID, initials, date of birth or any other identifier.
A7: How to use it (about 5 minutes per class per month)
A8: 1. Setup: type your school name and year (optional). Leave the other settings unless your policy says otherwise.
A9: 2. Classes: one row per class or group. Use a room or period label such as Rm 12 or Per 4, never a person's name. Choose the band and type the number of students enrolled.
A10: 3. Lessons: for each class, choose Yes, Partial or Not yet for each lesson. Orange-tinted blank cells mark the lessons that are sensitive for that band: they need a counselor heads-up and a family notice first.
A11: 4. HelpLadder: type how many Help Ladder practice sessions each class ran, and how many students practiced saying their first sentence aloud (a count).
A12: 5. Surveys (optional): only if your counsel approves the Assessment Pack surveys. Type class totals from the Class Tally Sheet: how many students answered, and how many gave the best answer on each of the three core items (listed on the Surveys sheet), before and after.
A13: 6. Sensitive: add one row each time a sensitive lesson is taught. Pick the class and the lesson from the lists. Add the lesson date and the date the family notice went home. Type counts only.
... A27: Setup, Classes, Lessons, HelpLadder, Surveys, Sensitive, Family: entry sheets. Summary: school summary by band, laid out like the Assessment Pack's administrator impact summary. Dashboard: key numbers and charts. Checks: data-quality flags. ChartData: values behind the charts (#N/A is deliberate: it makes a chart skip a suppressed value). Lists: drop-down lists and lesson titles.

Sheet Setup
A1: Setup [EXAMPLE DATA: made up, not a real school]
A2: © 2026 Competence Collective. Lesson text and teaching materials CC BY-NC 4.0. The Hackles name, logos, characters and artwork are not covered by that license: print and share them unaltered for classroom and family use; any other use needs written permission. [VERIFY with counsel]
A3: Optional: name and year. Change the thresholds only if your policy says to. Do not type any person's name.
A4: School or program name (optional) | B4: Example School
A5: School year | B5: 2026-27
A6: Smallest group to report as a percentage (suppression threshold) | B6: 10 | C6: Surveys: below this many students, show n<10 instead of a percentage. [VERIFY your district's rule]
A7: Opt-out rate to review (flag when at or above) | B7: 0.1 | C7: Only a flag for you to look at, not a target.
A8: Minimum days of family notice before a sensitive lesson | B8: 14 | C8: 14 days is the kit's suggestion. [COUNSEL TO CONFIRM your state and district rule]

Sheet Classes
A1: Classes [EXAMPLE DATA: made up, not a real school]
A2: © 2026 Competence Collective. Lesson text and teaching materials CC BY-NC 4.0. The Hackles name, logos, characters and artwork are not covered by that license: print and share them unaltered for classroom and family use; any other use needs written permission. [VERIFY with counsel]
A3: One row per class or group. Use a room or period label (for example Rm 12 or Per 4). Never a student's or teacher's name. Choose the band and type the number enrolled.
A5: # | B5: Class or group label (no names) | C5: Grade band | D5: Students enrolled (count) | E5: Core lessons delivered (of 10) | F5: Data check
A6: 1 | B6: Rm 101 | C6: Gr K-2 | D6: 22 | E6: =IF(B6="","",Lessons!Q6) | F6: =IF(B6="","",IF(Checks!K6>0,"Review","OK"))
A7: 2 | B7: Rm 104 | C7: Gr K-2 | D7: 20 | E7: =IF(B7="","",Lessons!Q7) | F7: =IF(B7="","",IF(Checks!K7>0,"Review","OK"))
A8: 3 | B8: Rm 301 | C8: Gr 3-5 | D8: 24 | E8: =IF(B8="","",Lessons!Q8) | F8: =IF(B8="","",IF(Checks!K8>0,"Review","OK"))
A9: 4 | B9: Rm 305 | C9: Gr 3-5 | D9: 23 | E9: =IF(B9="","",Lessons!Q9) | F9: =IF(B9="","",IF(Checks!K9>0,"Review","OK"))
A10: 5 | B10: Per 2 | C10: Gr 6-8 | D10: 27 | E10: =IF(B10="","",Lessons!Q10) | F10: =IF(B10="","",IF(Checks!K10>0,"Review","OK"))
A11: 6 | B11: Per 5 | C11: Gr 6-8 | D11: 25 | E11: =IF(B11="","",Lessons!Q11) | F11: =IF(B11="","",IF(Checks!K11>0,"Review","OK"))
A12: 7 | B12: Adv 9A | C12: Gr 9-12 | D12: 8 | E12: =IF(B12="","",Lessons!Q12) | F12: =IF(B12="","",IF(Checks!K12>0,"Review","OK"))
A13: 8 | E13: =IF(B13="","",Lessons!Q13) | F13: =IF(B13="","",IF(Checks!K13>0,"Review","OK"))
A14: 9 | E14: =IF(B14="","",Lessons!Q14) | F14: =IF(B14="","",IF(Checks!K14>0,"Review","OK"))
A15: 10 | E15: =IF(B15="","",Lessons!Q15) | F15: =IF(B15="","",IF(Checks!K15>0,"Review","OK"))
A16: 11 | E16: =IF(B16="","",Lessons!Q16) | F16: =IF(B16="","",IF(Checks!K16>0,"Review","OK"))
A17: 12 | E17: =IF(B17="","",Lessons!Q17) | F17: =IF(B17="","",IF(Checks!K17>0,"Review","OK"))
A18: 13 | E18: =IF(B18="","",Lessons!Q18) | F18: =IF(B18="","",IF(Checks!K18>0,"Review","OK"))
A19: 14 | E19: =IF(B19="","",Lessons!Q19) | F19: =IF(B19="","",IF(Checks!K19>0,"Review","OK"))
A20: 15 | E20: =IF(B20="","",Lessons!Q20) | F20: =IF(B20="","",IF(Checks!K20>0,"Review","OK"))
A21: 16 | E21: =IF(B21="","",Lessons!Q21) | F21: =IF(B21="","",IF(Checks!K21>0,"Review","OK"))
A22: 17 | E22: =IF(B22="","",Lessons!Q22) | F22: =IF(B22="","",IF(Checks!K22>0,"Review","OK"))
A23: 18 | E23: =IF(B23="","",Lessons!Q23) | F23: =IF(B23="","",IF(Checks!K23>0,"Review","OK"))
A24: 19 | E24: =IF(B24="","",Lessons!Q24) | F24: =IF(B24="","",IF(Checks!K24>0,"Review","OK"))
... A45: 40 | E45: =IF(B45="","",Lessons!Q45) | F45: =IF(B45="","",IF(Checks!K45>0,"Review","OK"))

Sheet Lessons
A1: Lessons delivered [EXAMPLE DATA: made up, not a real school]
A2: © 2026 Competence Collective. Lesson text and teaching materials CC BY-NC 4.0. The Hackles name, logos, characters and artwork are not covered by that license: print and share them unaltered for classroom and family use; any other use needs written permission. [VERIFY with counsel]
A3: Choose Yes, Partial or Not yet for each lesson. L1 to L10 are the core lessons. P1 to P4 are the Plus lessons (grades 6-12 only). Orange-tinted blank cells are sensitive lessons for that band: counselor heads-up and family notice first.
A5: Class | B5: Band | C5: L1 | D5: L2 | E5: L3 | F5: L4 | G5: L5 | H5: L6 | I5: L7 | J5: L8 | K5: L9 | L5: L10 | M5: P1 | N5: P2 | O5: P3 | P5: P4 | Q5: Core delivered (Yes) | R5: Core partial | S5: Core completion % | T5: Plus delivered (Yes)
A6: =IF(Classes!B6="","",Classes!B6) | B6: =IF(Classes!B6="","",IF(Classes!C6="","",Classes!C6)) | C6: Yes | D6: Yes | E6: Yes | F6: Yes | G6: Yes | H6: Yes | I6: Yes | J6: Partial | K6: Not yet | L6: Not yet | Q6: =IF(A6="","",COUNTIF(C6:L6,"Yes")) | R6: =IF(A6="","",COUNTIF(C6:L6,"Partial")) | S6: =IF(A6="","",Q6/10) | T6: =IF(A6="","",COUNTIF(M6:P6,"Yes"))
A7: =IF(Classes!B7="","",Classes!B7) | B7: =IF(Classes!B7="","",IF(Classes!C7="","",Classes!C7)) | C7: Yes | D7: Yes | E7: Yes | F7: Yes | G7: Yes | H7: Yes | I7: Partial | J7: Not yet | K7: Not yet | L7: Not yet | Q7: =IF(A7="","",COUNTIF(C7:L7,"Yes")) | R7: =IF(A7="","",COUNTIF(C7:L7,"Partial")) | S7: =IF(A7="","",Q7/10) | T7: =IF(A7="","",COUNTIF(M7:P7,"Yes"))
A8: =IF(Classes!B8="","",Classes!B8) | B8: =IF(Classes!B8="","",IF(Classes!C8="","",Classes!C8)) | C8: Yes | D8: Yes | E8: Yes | F8: Yes | G8: Yes | H8: Yes | I8: Yes | J8: Yes | K8: Not yet | L8: Not yet | Q8: =IF(A8="","",COUNTIF(C8:L8,"Yes")) | R8: =IF(A8="","",COUNTIF(C8:L8,"Partial")) | S8: =IF(A8="","",Q8/10) | T8: =IF(A8="","",COUNTIF(M8:P8,"Yes"))
A9: =IF(Classes!B9="","",Classes!B9) | B9: =IF(Classes!B9="","",IF(Classes!C9="","",Classes!C9)) | C9: Yes | D9: Yes | E9: Yes | F9: Yes | G9: Yes | H9: Partial | I9: Not yet | J9: Not yet | K9: Not yet | L9: Not yet | Q9: =IF(A9="","",COUNTIF(C9:L9,"Yes")) | R9: =IF(A9="","",COUNTIF(C9:L9,"Partial")) | S9: =IF(A9="","",Q9/10) | T9: =IF(A9="","",COUNTIF(M9:P9,"Yes"))
A10: =IF(Classes!B10="","",Classes!B10) | B10: =IF(Classes!B10="","",IF(Classes!C10="","",Classes!C10)) | C10: Yes | D10: Yes | E10: Yes | F10: Yes | G10: Yes | H10: Yes | I10: Yes | J10: Yes | K10: Yes | L10: Not yet | M10: Not yet | N10: Not yet | O10: Yes | Q10: =IF(A10="","",COUNTIF(C10:L10,"Yes")) | R10: =IF(A10="","",COUNTIF(C10:L10,"Partial")) | S10: =IF(A10="","",Q10/10) | T10: =IF(A10="","",COUNTIF(M10:P10,"Yes"))
A11: =IF(Classes!B11="","",Classes!B11) | B11: =IF(Classes!B11="","",IF(Classes!C11="","",Classes!C11)) | C11: Yes | D11: Yes | E11: Yes | F11: Yes | G11: Yes | H11: Yes | I11: Yes | J11: Yes | K11: Partial | L11: Not yet | M11: Not yet | N11: Not yet | O11: Partial | Q11: =IF(A11="","",COUNTIF(C11:L11,"Yes")) | R11: =IF(A11="","",COUNTIF(C11:L11,"Partial")) | S11: =IF(A11="","",Q11/10) | T11: =IF(A11="","",COUNTIF(M11:P11,"Yes"))
A12: =IF(Classes!B12="","",Classes!B12) | B12: =IF(Classes!B12="","",IF(Classes!C12="","",Classes!C12)) | C12: Yes | D12: Yes | E12: Yes | F12: Yes | G12: Yes | H12: Yes | I12: Not yet | J12: Not yet | K12: Not yet | L12: Not yet | M12: Not yet | N12: Not yet | O12: Yes | P12: Not yet | Q12: =IF(A12="","",COUNTIF(C12:L12,"Yes")) | R12: =IF(A12="","",COUNTIF(C12:L12,"Partial")) | S12: =IF(A12="","",Q12/10) | T12: =IF(A12="","",COUNTIF(M12:P12,"Yes"))
A13: =IF(Classes!B13="","",Classes!B13) | B13: =IF(Classes!B13="","",IF(Classes!C13="","",Classes!C13)) | Q13: =IF(A13="","",COUNTIF(C13:L13,"Yes")) | R13: =IF(A13="","",COUNTIF(C13:L13,"Partial")) | S13: =IF(A13="","",Q13/10) | T13: =IF(A13="","",COUNTIF(M13:P13,"Yes"))
A14: =IF(Classes!B14="","",Classes!B14) | B14: =IF(Classes!B14="","",IF(Classes!C14="","",Classes!C14)) | Q14: =IF(A14="","",COUNTIF(C14:L14,"Yes")) | R14: =IF(A14="","",COUNTIF(C14:L14,"Partial")) | S14: =IF(A14="","",Q14/10) | T14: =IF(A14="","",COUNTIF(M14:P14,"Yes"))
A15: =IF(Classes!B15="","",Classes!B15) | B15: =IF(Classes!B15="","",IF(Classes!C15="","",Classes!C15)) | Q15: =IF(A15="","",COUNTIF(C15:L15,"Yes")) | R15: =IF(A15="","",COUNTIF(C15:L15,"Partial")) | S15: =IF(A15="","",Q15/10) | T15: =IF(A15="","",COUNTIF(M15:P15,"Yes"))
A16: =IF(Classes!B16="","",Classes!B16) | B16: =IF(Classes!B16="","",IF(Classes!C16="","",Classes!C16)) | Q16: =IF(A16="","",COUNTIF(C16:L16,"Yes")) | R16: =IF(A16="","",COUNTIF(C16:L16,"Partial")) | S16: =IF(A16="","",Q16/10) | T16: =IF(A16="","",COUNTIF(M16:P16,"Yes"))
A17: =IF(Classes!B17="","",Classes!B17) | B17: =IF(Classes!B17="","",IF(Classes!C17="","",Classes!C17)) | Q17: =IF(A17="","",COUNTIF(C17:L17,"Yes")) | R17: =IF(A17="","",COUNTIF(C17:L17,"Partial")) | S17: =IF(A17="","",Q17/10) | T17: =IF(A17="","",COUNTIF(M17:P17,"Yes"))
A18: =IF(Classes!B18="","",Classes!B18) | B18: =IF(Classes!B18="","",IF(Classes!C18="","",Classes!C18)) | Q18: =IF(A18="","",COUNTIF(C18:L18,"Yes")) | R18: =IF(A18="","",COUNTIF(C18:L18,"Partial")) | S18: =IF(A18="","",Q18/10) | T18: =IF(A18="","",COUNTIF(M18:P18,"Yes"))
A19: =IF(Classes!B19="","",Classes!B19) | B19: =IF(Classes!B19="","",IF(Classes!C19="","",Classes!C19)) | Q19: =IF(A19="","",COUNTIF(C19:L19,"Yes")) | R19: =IF(A19="","",COUNTIF(C19:L19,"Partial")) | S19: =IF(A19="","",Q19/10) | T19: =IF(A19="","",COUNTIF(M19:P19,"Yes"))
A20: =IF(Classes!B20="","",Classes!B20) | B20: =IF(Classes!B20="","",IF(Classes!C20="","",Classes!C20)) | Q20: =IF(A20="","",COUNTIF(C20:L20,"Yes")) | R20: =IF(A20="","",COUNTIF(C20:L20,"Partial")) | S20: =IF(A20="","",Q20/10) | T20: =IF(A20="","",COUNTIF(M20:P20,"Yes"))
A21: =IF(Classes!B21="","",Classes!B21) | B21: =IF(Classes!B21="","",IF(Classes!C21="","",Classes!C21)) | Q21: =IF(A21="","",COUNTIF(C21:L21,"Yes")) | R21: =IF(A21="","",COUNTIF(C21:L21,"Partial")) | S21: =IF(A21="","",Q21/10) | T21: =IF(A21="","",COUNTIF(M21:P21,"Yes"))
A22: =IF(Classes!B22="","",Classes!B22) | B22: =IF(Classes!B22="","",IF(Classes!C22="","",Classes!C22)) | Q22: =IF(A22="","",COUNTIF(C22:L22,"Yes")) | R22: =IF(A22="","",COUNTIF(C22:L22,"Partial")) | S22: =IF(A22="","",Q22/10) | T22: =IF(A22="","",COUNTIF(M22:P22,"Yes"))
A23: =IF(Classes!B23="","",Classes!B23) | B23: =IF(Classes!B23="","",IF(Classes!C23="","",Classes!C23)) | Q23: =IF(A23="","",COUNTIF(C23:L23,"Yes")) | R23: =IF(A23="","",COUNTIF(C23:L23,"Partial")) | S23: =IF(A23="","",Q23/10) | T23: =IF(A23="","",COUNTIF(M23:P23,"Yes"))
A24: =IF(Classes!B24="","",Classes!B24) | B24: =IF(Classes!B24="","",IF(Classes!C24="","",Classes!C24)) | Q24: =IF(A24="","",COUNTIF(C24:L24,"Yes")) | R24: =IF(A24="","",COUNTIF(C24:L24,"Partial")) | S24: =IF(A24="","",Q24/10) | T24: =IF(A24="","",COUNTIF(M24:P24,"Yes"))
... A45: =IF(Classes!B45="","",Classes!B45) | B45: =IF(Classes!B45="","",IF(Classes!C45="","",Classes!C45)) | Q45: =IF(A45="","",COUNTIF(C45:L45,"Yes")) | R45: =IF(A45="","",COUNTIF(C45:L45,"Partial")) | S45: =IF(A45="","",Q45/10) | T45: =IF(A45="","",COUNTIF(M45:P45,"Yes"))

Sheet HelpLadder
A1: Help Ladder practice [EXAMPLE DATA: made up, not a real school]
A2: © 2026 Competence Collective. Lesson text and teaching materials CC BY-NC 4.0. The Hackles name, logos, characters and artwork are not covered by that license: print and share them unaltered for classroom and family use; any other use needs written permission. [VERIFY with counsel]
A3: Counts only. A practice session is any class meeting where students practiced the Help Ladder or their first sentence for telling a trusted adult. The rubric columns are optional counts from the Assessment Pack rubric (students scoring 3 or 4 on the Help Ladder skill).
A5: Class | B5: Band | C5: Students enrolled | D5: Practice sessions (count) | E5: Students who practiced the first sentence aloud | F5: Rubric 3 or 4 early (students, optional) | G5: Rubric 3 or 4 at end (students, optional) | H5: % who practiced aloud | I5: Rubric change (students)
A6: =IF(Classes!B6="","",Classes!B6) | B6: =IF(Classes!B6="","",IF(Classes!C6="","",Classes!C6)) | C6: =IF(A6="","",IF(Classes!D6="","",Classes!D6)) | D6: 4 | E6: 18 | F6: 6 | G6: 15 | H6: =IF(OR(A6="",C6="",C6=0,E6=""),"",E6/C6) | I6: =IF(OR(A6="",F6="",G6=""),"",G6-F6)
A7: =IF(Classes!B7="","",Classes!B7) | B7: =IF(Classes!B7="","",IF(Classes!C7="","",Classes!C7)) | C7: =IF(A7="","",IF(Classes!D7="","",Classes!D7)) | D7: 3 | E7: 15 | F7: 5 | G7: 12 | H7: =IF(OR(A7="",C7="",C7=0,E7=""),"",E7/C7) | I7: =IF(OR(A7="",F7="",G7=""),"",G7-F7)
A8: =IF(Classes!B8="","",Classes!B8) | B8: =IF(Classes!B8="","",IF(Classes!C8="","",Classes!C8)) | C8: =IF(A8="","",IF(Classes!D8="","",Classes!D8)) | D8: 5 | E8: 22 | F8: 8 | G8: 19 | H8: =IF(OR(A8="",C8="",C8=0,E8=""),"",E8/C8) | I8: =IF(OR(A8="",F8="",G8=""),"",G8-F8)
A9: =IF(Classes!B9="","",Classes!B9) | B9: =IF(Classes!B9="","",IF(Classes!C9="","",Classes!C9)) | C9: =IF(A9="","",IF(Classes!D9="","",Classes!D9)) | D9: 3 | E9: 17 | F9: 7 | G9: 13 | H9: =IF(OR(A9="",C9="",C9=0,E9=""),"",E9/C9) | I9: =IF(OR(A9="",F9="",G9=""),"",G9-F9)
A10: =IF(Classes!B10="","",Classes!B10) | B10: =IF(Classes!B10="","",IF(Classes!C10="","",Classes!C10)) | C10: =IF(A10="","",IF(Classes!D10="","",Classes!D10)) | D10: 6 | E10: 25 | F10: 9 | G10: 21 | H10: =IF(OR(A10="",C10="",C10=0,E10=""),"",E10/C10) | I10: =IF(OR(A10="",F10="",G10=""),"",G10-F10)
A11: =IF(Classes!B11="","",Classes!B11) | B11: =IF(Classes!B11="","",IF(Classes!C11="","",Classes!C11)) | C11: =IF(A11="","",IF(Classes!D11="","",Classes!D11)) | D11: 5 | E11: 21 | F11: 8 | G11: 18 | H11: =IF(OR(A11="",C11="",C11=0,E11=""),"",E11/C11) | I11: =IF(OR(A11="",F11="",G11=""),"",G11-F11)
A12: =IF(Classes!B12="","",Classes!B12) | B12: =IF(Classes!B12="","",IF(Classes!C12="","",Classes!C12)) | C12: =IF(A12="","",IF(Classes!D12="","",Classes!D12)) | D12: 3 | E12: 7 | F12: 3 | G12: 6 | H12: =IF(OR(A12="",C12="",C12=0,E12=""),"",E12/C12) | I12: =IF(OR(A12="",F12="",G12=""),"",G12-F12)
A13: =IF(Classes!B13="","",Classes!B13) | B13: =IF(Classes!B13="","",IF(Classes!C13="","",Classes!C13)) | C13: =IF(A13="","",IF(Classes!D13="","",Classes!D13)) | H13: =IF(OR(A13="",C13="",C13=0,E13=""),"",E13/C13) | I13: =IF(OR(A13="",F13="",G13=""),"",G13-F13)
A14: =IF(Classes!B14="","",Classes!B14) | B14: =IF(Classes!B14="","",IF(Classes!C14="","",Classes!C14)) | C14: =IF(A14="","",IF(Classes!D14="","",Classes!D14)) | H14: =IF(OR(A14="",C14="",C14=0,E14=""),"",E14/C14) | I14: =IF(OR(A14="",F14="",G14=""),"",G14-F14)
A15: =IF(Classes!B15="","",Classes!B15) | B15: =IF(Classes!B15="","",IF(Classes!C15="","",Classes!C15)) | C15: =IF(A15="","",IF(Classes!D15="","",Classes!D15)) | H15: =IF(OR(A15="",C15="",C15=0,E15=""),"",E15/C15) | I15: =IF(OR(A15="",F15="",G15=""),"",G15-F15)
A16: =IF(Classes!B16="","",Classes!B16) | B16: =IF(Classes!B16="","",IF(Classes!C16="","",Classes!C16)) | C16: =IF(A16="","",IF(Classes!D16="","",Classes!D16)) | H16: =IF(OR(A16="",C16="",C16=0,E16=""),"",E16/C16) | I16: =IF(OR(A16="",F16="",G16=""),"",G16-F16)
A17: =IF(Classes!B17="","",Classes!B17) | B17: =IF(Classes!B17="","",IF(Classes!C17="","",Classes!C17)) | C17: =IF(A17="","",IF(Classes!D17="","",Classes!D17)) | H17: =IF(OR(A17="",C17="",C17=0,E17=""),"",E17/C17) | I17: =IF(OR(A17="",F17="",G17=""),"",G17-F17)
A18: =IF(Classes!B18="","",Classes!B18) | B18: =IF(Classes!B18="","",IF(Classes!C18="","",Classes!C18)) | C18: =IF(A18="","",IF(Classes!D18="","",Classes!D18)) | H18: =IF(OR(A18="",C18="",C18=0,E18=""),"",E18/C18) | I18: =IF(OR(A18="",F18="",G18=""),"",G18-F18)
A19: =IF(Classes!B19="","",Classes!B19) | B19: =IF(Classes!B19="","",IF(Classes!C19="","",Classes!C19)) | C19: =IF(A19="","",IF(Classes!D19="","",Classes!D19)) | H19: =IF(OR(A19="",C19="",C19=0,E19=""),"",E19/C19) | I19: =IF(OR(A19="",F19="",G19=""),"",G19-F19)
A20: =IF(Classes!B20="","",Classes!B20) | B20: =IF(Classes!B20="","",IF(Classes!C20="","",Classes!C20)) | C20: =IF(A20="","",IF(Classes!D20="","",Classes!D20)) | H20: =IF(OR(A20="",C20="",C20=0,E20=""),"",E20/C20) | I20: =IF(OR(A20="",F20="",G20=""),"",G20-F20)
A21: =IF(Classes!B21="","",Classes!B21) | B21: =IF(Classes!B21="","",IF(Classes!C21="","",Classes!C21)) | C21: =IF(A21="","",IF(Classes!D21="","",Classes!D21)) | H21: =IF(OR(A21="",C21="",C21=0,E21=""),"",E21/C21) | I21: =IF(OR(A21="",F21="",G21=""),"",G21-F21)
A22: =IF(Classes!B22="","",Classes!B22) | B22: =IF(Classes!B22="","",IF(Classes!C22="","",Classes!C22)) | C22: =IF(A22="","",IF(Classes!D22="","",Classes!D22)) | H22: =IF(OR(A22="",C22="",C22=0,E22=""),"",E22/C22) | I22: =IF(OR(A22="",F22="",G22=""),"",G22-F22)
A23: =IF(Classes!B23="","",Classes!B23) | B23: =IF(Classes!B23="","",IF(Classes!C23="","",Classes!C23)) | C23: =IF(A23="","",IF(Classes!D23="","",Classes!D23)) | H23: =IF(OR(A23="",C23="",C23=0,E23=""),"",E23/C23) | I23: =IF(OR(A23="",F23="",G23=""),"",G23-F23)
A24: =IF(Classes!B24="","",Classes!B24) | B24: =IF(Classes!B24="","",IF(Classes!C24="","",Classes!C24)) | C24: =IF(A24="","",IF(Classes!D24="","",Classes!D24)) | H24: =IF(OR(A24="",C24="",C24=0,E24=""),"",E24/C24) | I24: =IF(OR(A24="",F24="",G24=""),"",G24-F24)
... A45: =IF(Classes!B45="","",Classes!B45) | B45: =IF(Classes!B45="","",IF(Classes!C45="","",Classes!C45)) | C45: =IF(A45="","",IF(Classes!D45="","",Classes!D45)) | H45: =IF(OR(A45="",C45="",C45=0,E45=""),"",E45/C45) | I45: =IF(OR(A45="",F45="",G45=""),"",G45-F45)

Sheet Surveys
A1: Pre and post survey tallies (optional) [EXAMPLE DATA: made up, not a real school]
A2: © 2026 Competence Collective. Lesson text and teaching materials CC BY-NC 4.0. The Hackles name, logos, characters and artwork are not covered by that license: print and share them unaltered for classroom and family use; any other use needs written permission. [VERIFY with counsel]
A3: Use only if your counsel has approved the Assessment Pack surveys for your school. Type class totals from the Class Tally Sheet: students who answered, and students who gave the best answer on each of the three core items. Core items by band: K-2 items 1, 4, 5; 3-5 items 1, 4, 7; 6-8 items 2, 5, 7; 9-12 items 1, 4, 10. Confidence is the number rating 3 or higher (4 or higher on a 5-point scale) on the confidence-to-tell item.
A5: Class | B5: Band | C5: Students enrolled | D5: PRE: students who answered | E5: PRE: best answer core item 1 | F5: PRE: core item 2 | G5: PRE: core item 3 | H5: PRE: confident to tell (count) | I5: POST: students who answered | J5: POST: best answer core item 1 | K5: POST: core item 2 | L5: POST: core item 3 | M5: POST: confident to tell (count) | N5: Matched pre/post pairs (count) | O5: Tell-Readiness before % | P5: Tell-Readiness after % | Q5: Change (percentage points) | R5: Confident to tell before % | S5: Confident to tell after %
A6: =IF(Classes!B6="","",Classes!B6) | B6: =IF(Classes!B6="","",IF(Classes!C6="","",Classes!C6)) | C6: =IF(A6="","",IF(Classes!D6="","",Classes!D6)) | D6: 21 | E6: 8 | F6: 10 | G6: 9 | H6: 11 | I6: 20 | J6: 15 | K6: 17 | L6: 16 | M6: 16 | N6: 19 | O6: =IF(OR(A6="",D6="",D6=0),"",(E6+F6+G6)/(3*D6)) | P6: =IF(OR(A6="",I6="",I6=0),"",(J6+K6+L6)/(3*I6)) | Q6: =IF(OR(O6="",P6=""),"",(P6-O6)*100) | R6: =IF(OR(A6="",D6="",D6=0,H6=""),"",H6/D6) | S6: =IF(OR(A6="",I6="",I6=0,M6=""),"",M6/I6)
A7: =IF(Classes!B7="","",Classes!B7) | B7: =IF(Classes!B7="","",IF(Classes!C7="","",Classes!C7)) | C7: =IF(A7="","",IF(Classes!D7="","",Classes!D7)) | D7: 19 | E7: 7 | F7: 9 | G7: 8 | H7: 9 | I7: 18 | J7: 13 | K7: 14 | L7: 14 | M7: 13 | N7: 17 | O7: =IF(OR(A7="",D7="",D7=0),"",(E7+F7+G7)/(3*D7)) | P7: =IF(OR(A7="",I7="",I7=0),"",(J7+K7+L7)/(3*I7)) | Q7: =IF(OR(O7="",P7=""),"",(P7-O7)*100) | R7: =IF(OR(A7="",D7="",D7=0,H7=""),"",H7/D7) | S7: =IF(OR(A7="",I7="",I7=0,M7=""),"",M7/I7)
A8: =IF(Classes!B8="","",Classes!B8) | B8: =IF(Classes!B8="","",IF(Classes!C8="","",Classes!C8)) | C8: =IF(A8="","",IF(Classes!D8="","",Classes!D8)) | D8: 23 | E8: 10 | F8: 12 | G8: 11 | H8: 12 | I8: 22 | J8: 17 | K8: 18 | L8: 19 | M8: 17 | N8: 21 | O8: =IF(OR(A8="",D8="",D8=0),"",(E8+F8+G8)/(3*D8)) | P8: =IF(OR(A8="",I8="",I8=0),"",(J8+K8+L8)/(3*I8)) | Q8: =IF(OR(O8="",P8=""),"",(P8-O8)*100) | R8: =IF(OR(A8="",D8="",D8=0,H8=""),"",H8/D8) | S8: =IF(OR(A8="",I8="",I8=0,M8=""),"",M8/I8)
A9: =IF(Classes!B9="","",Classes!B9) | B9: =IF(Classes!B9="","",IF(Classes!C9="","",Classes!C9)) | C9: =IF(A9="","",IF(Classes!D9="","",Classes!D9)) | D9: 22 | E9: 9 | F9: 11 | G9: 10 | H9: 11 | I9: 21 | J9: 14 | K9: 16 | L9: 15 | M9: 14 | N9: 20 | O9: =IF(OR(A9="",D9="",D9=0),"",(E9+F9+G9)/(3*D9)) | P9: =IF(OR(A9="",I9="",I9=0),"",(J9+K9+L9)/(3*I9)) | Q9: =IF(OR(O9="",P9=""),"",(P9-O9)*100) | R9: =IF(OR(A9="",D9="",D9=0,H9=""),"",H9/D9) | S9: =IF(OR(A9="",I9="",I9=0,M9=""),"",M9/I9)
A10: =IF(Classes!B10="","",Classes!B10) | B10: =IF(Classes!B10="","",IF(Classes!C10="","",Classes!C10)) | C10: =IF(A10="","",IF(Classes!D10="","",Classes!D10)) | D10: 26 | E10: 11 | F10: 13 | G10: 12 | H10: 13 | I10: 25 | J10: 20 | K10: 22 | L10: 21 | M10: 20 | N10: 24 | O10: =IF(OR(A10="",D10="",D10=0),"",(E10+F10+G10)/(3*D10)) | P10: =IF(OR(A10="",I10="",I10=0),"",(J10+K10+L10)/(3*I10)) | Q10: =IF(OR(O10="",P10=""),"",(P10-O10)*100) | R10: =IF(OR(A10="",D10="",D10=0,H10=""),"",H10/D10) | S10: =IF(OR(A10="",I10="",I10=0,M10=""),"",M10/I10)
A11: =IF(Classes!B11="","",Classes!B11) | B11: =IF(Classes!B11="","",IF(Classes!C11="","",Classes!C11)) | C11: =IF(A11="","",IF(Classes!D11="","",Classes!D11)) | D11: 24 | E11: 10 | F11: 12 | G11: 11 | H11: 12 | I11: 23 | J11: 18 | K11: 19 | L11: 19 | M11: 18 | N11: 22 | O11: =IF(OR(A11="",D11="",D11=0),"",(E11+F11+G11)/(3*D11)) | P11: =IF(OR(A11="",I11="",I11=0),"",(J11+K11+L11)/(3*I11)) | Q11: =IF(OR(O11="",P11=""),"",(P11-O11)*100) | R11: =IF(OR(A11="",D11="",D11=0,H11=""),"",H11/D11) | S11: =IF(OR(A11="",I11="",I11=0,M11=""),"",M11/I11)
A12: =IF(Classes!B12="","",Classes!B12) | B12: =IF(Classes!B12="","",IF(Classes!C12="","",Classes!C12)) | C12: =IF(A12="","",IF(Classes!D12="","",Classes!D12)) | D12: 8 | E12: 3 | F12: 4 | G12: 3 | H12: 4 | I12: 7 | J12: 5 | K12: 6 | L12: 5 | M12: 5 | N12: 7 | O12: =IF(OR(A12="",D12="",D12=0),"",(E12+F12+G12)/(3*D12)) | P12: =IF(OR(A12="",I12="",I12=0),"",(J12+K12+L12)/(3*I12)) | Q12: =IF(OR(O12="",P12=""),"",(P12-O12)*100) | R12: =IF(OR(A12="",D12="",D12=0,H12=""),"",H12/D12) | S12: =IF(OR(A12="",I12="",I12=0,M12=""),"",M12/I12)
A13: =IF(Classes!B13="","",Classes!B13) | B13: =IF(Classes!B13="","",IF(Classes!C13="","",Classes!C13)) | C13: =IF(A13="","",IF(Classes!D13="","",Classes!D13)) | O13: =IF(OR(A13="",D13="",D13=0),"",(E13+F13+G13)/(3*D13)) | P13: =IF(OR(A13="",I13="",I13=0),"",(J13+K13+L13)/(3*I13)) | Q13: =IF(OR(O13="",P13=""),"",(P13-O13)*100) | R13: =IF(OR(A13="",D13="",D13=0,H13=""),"",H13/D13) | S13: =IF(OR(A13="",I13="",I13=0,M13=""),"",M13/I13)
A14: =IF(Classes!B14="","",Classes!B14) | B14: =IF(Classes!B14="","",IF(Classes!C14="","",Classes!C14)) | C14: =IF(A14="","",IF(Classes!D14="","",Classes!D14)) | O14: =IF(OR(A14="",D14="",D14=0),"",(E14+F14+G14)/(3*D14)) | P14: =IF(OR(A14="",I14="",I14=0),"",(J14+K14+L14)/(3*I14)) | Q14: =IF(OR(O14="",P14=""),"",(P14-O14)*100) | R14: =IF(OR(A14="",D14="",D14=0,H14=""),"",H14/D14) | S14: =IF(OR(A14="",I14="",I14=0,M14=""),"",M14/I14)
A15: =IF(Classes!B15="","",Classes!B15) | B15: =IF(Classes!B15="","",IF(Classes!C15="","",Classes!C15)) | C15: =IF(A15="","",IF(Classes!D15="","",Classes!D15)) | O15: =IF(OR(A15="",D15="",D15=0),"",(E15+F15+G15)/(3*D15)) | P15: =IF(OR(A15="",I15="",I15=0),"",(J15+K15+L15)/(3*I15)) | Q15: =IF(OR(O15="",P15=""),"",(P15-O15)*100) | R15: =IF(OR(A15="",D15="",D15=0,H15=""),"",H15/D15) | S15: =IF(OR(A15="",I15="",I15=0,M15=""),"",M15/I15)
A16: =IF(Classes!B16="","",Classes!B16) | B16: =IF(Classes!B16="","",IF(Classes!C16="","",Classes!C16)) | C16: =IF(A16="","",IF(Classes!D16="","",Classes!D16)) | O16: =IF(OR(A16="",D16="",D16=0),"",(E16+F16+G16)/(3*D16)) | P16: =IF(OR(A16="",I16="",I16=0),"",(J16+K16+L16)/(3*I16)) | Q16: =IF(OR(O16="",P16=""),"",(P16-O16)*100) | R16: =IF(OR(A16="",D16="",D16=0,H16=""),"",H16/D16) | S16: =IF(OR(A16="",I16="",I16=0,M16=""),"",M16/I16)
A17: =IF(Classes!B17="","",Classes!B17) | B17: =IF(Classes!B17="","",IF(Classes!C17="","",Classes!C17)) | C17: =IF(A17="","",IF(Classes!D17="","",Classes!D17)) | O17: =IF(OR(A17="",D17="",D17=0),"",(E17+F17+G17)/(3*D17)) | P17: =IF(OR(A17="",I17="",I17=0),"",(J17+K17+L17)/(3*I17)) | Q17: =IF(OR(O17="",P17=""),"",(P17-O17)*100) | R17: =IF(OR(A17="",D17="",D17=0,H17=""),"",H17/D17) | S17: =IF(OR(A17="",I17="",I17=0,M17=""),"",M17/I17)
A18: =IF(Classes!B18="","",Classes!B18) | B18: =IF(Classes!B18="","",IF(Classes!C18="","",Classes!C18)) | C18: =IF(A18="","",IF(Classes!D18="","",Classes!D18)) | O18: =IF(OR(A18="",D18="",D18=0),"",(E18+F18+G18)/(3*D18)) | P18: =IF(OR(A18="",I18="",I18=0),"",(J18+K18+L18)/(3*I18)) | Q18: =IF(OR(O18="",P18=""),"",(P18-O18)*100) | R18: =IF(OR(A18="",D18="",D18=0,H18=""),"",H18/D18) | S18: =IF(OR(A18="",I18="",I18=0,M18=""),"",M18/I18)
A19: =IF(Classes!B19="","",Classes!B19) | B19: =IF(Classes!B19="","",IF(Classes!C19="","",Classes!C19)) | C19: =IF(A19="","",IF(Classes!D19="","",Classes!D19)) | O19: =IF(OR(A19="",D19="",D19=0),"",(E19+F19+G19)/(3*D19)) | P19: =IF(OR(A19="",I19="",I19=0),"",(J19+K19+L19)/(3*I19)) | Q19: =IF(OR(O19="",P19=""),"",(P19-O19)*100) | R19: =IF(OR(A19="",D19="",D19=0,H19=""),"",H19/D19) | S19: =IF(OR(A19="",I19="",I19=0,M19=""),"",M19/I19)
A20: =IF(Classes!B20="","",Classes!B20) | B20: =IF(Classes!B20="","",IF(Classes!C20="","",Classes!C20)) | C20: =IF(A20="","",IF(Classes!D20="","",Classes!D20)) | O20: =IF(OR(A20="",D20="",D20=0),"",(E20+F20+G20)/(3*D20)) | P20: =IF(OR(A20="",I20="",I20=0),"",(J20+K20+L20)/(3*I20)) | Q20: =IF(OR(O20="",P20=""),"",(P20-O20)*100) | R20: =IF(OR(A20="",D20="",D20=0,H20=""),"",H20/D20) | S20: =IF(OR(A20="",I20="",I20=0,M20=""),"",M20/I20)
A21: =IF(Classes!B21="","",Classes!B21) | B21: =IF(Classes!B21="","",IF(Classes!C21="","",Classes!C21)) | C21: =IF(A21="","",IF(Classes!D21="","",Classes!D21)) | O21: =IF(OR(A21="",D21="",D21=0),"",(E21+F21+G21)/(3*D21)) | P21: =IF(OR(A21="",I21="",I21=0),"",(J21+K21+L21)/(3*I21)) | Q21: =IF(OR(O21="",P21=""),"",(P21-O21)*100) | R21: =IF(OR(A21="",D21="",D21=0,H21=""),"",H21/D21) | S21: =IF(OR(A21="",I21="",I21=0,M21=""),"",M21/I21)
A22: =IF(Classes!B22="","",Classes!B22) | B22: =IF(Classes!B22="","",IF(Classes!C22="","",Classes!C22)) | C22: =IF(A22="","",IF(Classes!D22="","",Classes!D22)) | O22: =IF(OR(A22="",D22="",D22=0),"",(E22+F22+G22)/(3*D22)) | P22: =IF(OR(A22="",I22="",I22=0),"",(J22+K22+L22)/(3*I22)) | Q22: =IF(OR(O22="",P22=""),"",(P22-O22)*100) | R22: =IF(OR(A22="",D22="",D22=0,H22=""),"",H22/D22) | S22: =IF(OR(A22="",I22="",I22=0,M22=""),"",M22/I22)
A23: =IF(Classes!B23="","",Classes!B23) | B23: =IF(Classes!B23="","",IF(Classes!C23="","",Classes!C23)) | C23: =IF(A23="","",IF(Classes!D23="","",Classes!D23)) | O23: =IF(OR(A23="",D23="",D23=0),"",(E23+F23+G23)/(3*D23)) | P23: =IF(OR(A23="",I23="",I23=0),"",(J23+K23+L23)/(3*I23)) | Q23: =IF(OR(O23="",P23=""),"",(P23-O23)*100) | R23: =IF(OR(A23="",D23="",D23=0,H23=""),"",H23/D23) | S23: =IF(OR(A23="",I23="",I23=0,M23=""),"",M23/I23)
A24: =IF(Classes!B24="","",Classes!B24) | B24: =IF(Classes!B24="","",IF(Classes!C24="","",Classes!C24)) | C24: =IF(A24="","",IF(Classes!D24="","",Classes!D24)) | O24: =IF(OR(A24="",D24="",D24=0),"",(E24+F24+G24)/(3*D24)) | P24: =IF(OR(A24="",I24="",I24=0),"",(J24+K24+L24)/(3*I24)) | Q24: =IF(OR(O24="",P24=""),"",(P24-O24)*100) | R24: =IF(OR(A24="",D24="",D24=0,H24=""),"",H24/D24) | S24: =IF(OR(A24="",I24="",I24=0,M24=""),"",M24/I24)
... A45: =IF(Classes!B45="","",Classes!B45) | B45: =IF(Classes!B45="","",IF(Classes!C45="","",Classes!C45)) | C45: =IF(A45="","",IF(Classes!D45="","",Classes!D45)) | O45: =IF(OR(A45="",D45="",D45=0),"",(E45+F45+G45)/(3*D45)) | P45: =IF(OR(A45="",I45="",I45=0),"",(J45+K45+L45)/(3*I45)) | Q45: =IF(OR(O45="",P45=""),"",(P45-O45)*100) | R45: =IF(OR(A45="",D45="",D45=0,H45=""),"",H45/D45) | S45: =IF(OR(A45="",I45="",I45=0,M45=""),"",M45/I45)

Sheet Sensitive
A1: Sensitive lessons: notices, opt-outs and support [EXAMPLE DATA: made up, not a real school]
A2: © 2026 Competence Collective. Lesson text and teaching materials CC BY-NC 4.0. The Hackles name, logos, characters and artwork are not covered by that license: print and share them unaltered for classroom and family use; any other use needs written permission. [VERIFY with counsel]
A3: One row each time a sensitive lesson is taught in a class. Pick the class and the lesson. Dates are the dates on the calendar. Everything else is a count. Never record which family opted out or which child spoke to the counselor. Include the disclosure, referral and report counts only if your policy permits.
A5: Class | B5: Band (from lesson) | C5: Sensitive lesson | D5: Lesson date | E5: Family notice sent (date) | F5: Days of notice | G5: Notice check | H5: Counselor heads-up sent | I5: Counselor available during lesson | J5: Students enrolled | K5: Opt-out requests (count) | L5: Alternate activity offered | M5: Opt-out rate | N5: Students who asked to talk (count) | O5: Concerns or disclosures raised (count) | P5: Referred to counselor (count) | Q5: Reports made as required (count) | R5: Issues to review
A6: Rm 101 | B6: =IF(C6="","",LEFT(C6,FIND(" |",C6)-1)) | C6: Gr K-2 | L6 Online Friends vs. Real Friends | D6: 46338 | E6: 46322 | F6: =IF(OR(D6="",E6=""),"",D6-E6) | G6: =IF(F6="","",IF(F6>=Setup!$B$8,"OK","Short")) | H6: Yes | I6: Yes | J6: =IF(OR(A6="",C6=""),"",IFERROR(INDEX(Classes!$D$6:$D$45,MATCH(A6,Classes!$B$6:$B$45,0)),"")) | K6: 1 | L6: Yes | M6: =IF(OR(J6="",J6=0,K6=""),"",K6/J6) | N6: 2 | O6: 1 | P6: 1 | Q6: 0 | R6: =IF(C6="","",IF(A6="",1,0)+IF(J6="",1,0)+IF(AND(J6<>"",K6<>""),IF(K6>J6,1,0),0)+IF(G6="Short",1,0)+IF(I6="No",1,0)+IF(IFERROR(INDEX(Classes!$C$6:$C$45,MATCH(A6,Classes!$B$6:$B$45,0)),"")<>B6,1,0))
A7: Rm 104 | B7: =IF(C7="","",LEFT(C7,FIND(" |",C7)-1)) | C7: Gr K-2 | L6 Online Friends vs. Real Friends | D7: 46339 | E7: 46322 | F7: =IF(OR(D7="",E7=""),"",D7-E7) | G7: =IF(F7="","",IF(F7>=Setup!$B$8,"OK","Short")) | H7: Yes | I7: Yes | J7: =IF(OR(A7="",C7=""),"",IFERROR(INDEX(Classes!$D$6:$D$45,MATCH(A7,Classes!$B$6:$B$45,0)),"")) | K7: 0 | L7: Yes | M7: =IF(OR(J7="",J7=0,K7=""),"",K7/J7) | N7: 1 | O7: 0 | P7: 0 | Q7: 0 | R7: =IF(C7="","",IF(A7="",1,0)+IF(J7="",1,0)+IF(AND(J7<>"",K7<>""),IF(K7>J7,1,0),0)+IF(G7="Short",1,0)+IF(I7="No",1,0)+IF(IFERROR(INDEX(Classes!$C$6:$C$45,MATCH(A7,Classes!$B$6:$B$45,0)),"")<>B7,1,0))
A8: Rm 301 | B8: =IF(C8="","",LEFT(C8,FIND(" |",C8)-1)) | C8: Gr 3-5 | L1 The Help Ladder | D8: 46309 | E8: 46293 | F8: =IF(OR(D8="",E8=""),"",D8-E8) | G8: =IF(F8="","",IF(F8>=Setup!$B$8,"OK","Short")) | H8: Yes | I8: Yes | J8: =IF(OR(A8="",C8=""),"",IFERROR(INDEX(Classes!$D$6:$D$45,MATCH(A8,Classes!$B$6:$B$45,0)),"")) | K8: 0 | L8: Yes | M8: =IF(OR(J8="",J8=0,K8=""),"",K8/J8) | N8: 3 | O8: 1 | P8: 1 | Q8: 1 | R8: =IF(C8="","",IF(A8="",1,0)+IF(J8="",1,0)+IF(AND(J8<>"",K8<>""),IF(K8>J8,1,0),0)+IF(G8="Short",1,0)+IF(I8="No",1,0)+IF(IFERROR(INDEX(Classes!$C$6:$C$45,MATCH(A8,Classes!$B$6:$B$45,0)),"")<>B8,1,0))
A9: Rm 305 | B9: =IF(C9="","",LEFT(C9,FIND(" |",C9)-1)) | C9: Gr 3-5 | L1 The Help Ladder | D9: 46310 | E9: 46302 | F9: =IF(OR(D9="",E9=""),"",D9-E9) | G9: =IF(F9="","",IF(F9>=Setup!$B$8,"OK","Short")) | H9: Yes | I9: Yes | J9: =IF(OR(A9="",C9=""),"",IFERROR(INDEX(Classes!$D$6:$D$45,MATCH(A9,Classes!$B$6:$B$45,0)),"")) | K9: 1 | L9: Yes | M9: =IF(OR(J9="",J9=0,K9=""),"",K9/J9) | N9: 0 | O9: 0 | P9: 0 | Q9: 0 | R9: =IF(C9="","",IF(A9="",1,0)+IF(J9="",1,0)+IF(AND(J9<>"",K9<>""),IF(K9>J9,1,0),0)+IF(G9="Short",1,0)+IF(I9="No",1,0)+IF(IFERROR(INDEX(Classes!$C$6:$C$45,MATCH(A9,Classes!$B$6:$B$45,0)),"")<>B9,1,0))
A10: Per 2 | B10: =IF(C10="","",LEFT(C10,FIND(" |",C10)-1)) | C10: Gr 6-8 | L6 Grooming Patterns | D10: 46345 | E10: 46328 | F10: =IF(OR(D10="",E10=""),"",D10-E10) | G10: =IF(F10="","",IF(F10>=Setup!$B$8,"OK","Short")) | H10: Yes | I10: Yes | J10: =IF(OR(A10="",C10=""),"",IFERROR(INDEX(Classes!$D$6:$D$45,MATCH(A10,Classes!$B$6:$B$45,0)),"")) | K10: 2 | L10: Yes | M10: =IF(OR(J10="",J10=0,K10=""),"",K10/J10) | N10: 4 | O10: 2 | P10: 2 | Q10: 1 | R10: =IF(C10="","",IF(A10="",1,0)+IF(J10="",1,0)+IF(AND(J10<>"",K10<>""),IF(K10>J10,1,0),0)+IF(G10="Short",1,0)+IF(I10="No",1,0)+IF(IFERROR(INDEX(Classes!$C$6:$C$45,MATCH(A10,Classes!$B$6:$B$45,0)),"")<>B10,1,0))
A11: Per 5 | B11: =IF(C11="","",LEFT(C11,FIND(" |",C11)-1)) | C11: Gr 6-8 | L6 Grooming Patterns | D11: 46346 | E11: 46328 | F11: =IF(OR(D11="",E11=""),"",D11-E11) | G11: =IF(F11="","",IF(F11>=Setup!$B$8,"OK","Short")) | H11: Yes | I11: Yes | J11: =IF(OR(A11="",C11=""),"",IFERROR(INDEX(Classes!$D$6:$D$45,MATCH(A11,Classes!$B$6:$B$45,0)),"")) | K11: 1 | L11: Yes | M11: =IF(OR(J11="",J11=0,K11=""),"",K11/J11) | N11: 2 | O11: 0 | P11: 0 | Q11: 0 | R11: =IF(C11="","",IF(A11="",1,0)+IF(J11="",1,0)+IF(AND(J11<>"",K11<>""),IF(K11>J11,1,0),0)+IF(G11="Short",1,0)+IF(I11="No",1,0)+IF(IFERROR(INDEX(Classes!$C$6:$C$45,MATCH(A11,Classes!$B$6:$B$45,0)),"")<>B11,1,0))
A12: Per 2 | B12: =IF(C12="","",LEFT(C12,FIND(" |",C12)-1)) | C12: Gr 6-8 | L7 Pressure Online: Response Drill | D12: 46359 | E12: 46344 | F12: =IF(OR(D12="",E12=""),"",D12-E12) | G12: =IF(F12="","",IF(F12>=Setup!$B$8,"OK","Short")) | H12: Yes | I12: Yes | J12: =IF(OR(A12="",C12=""),"",IFERROR(INDEX(Classes!$D$6:$D$45,MATCH(A12,Classes!$B$6:$B$45,0)),"")) | K12: 3 | L12: Yes | M12: =IF(OR(J12="",J12=0,K12=""),"",K12/J12) | N12: 5 | O12: 1 | P12: 1 | Q12: 1 | R12: =IF(C12="","",IF(A12="",1,0)+IF(J12="",1,0)+IF(AND(J12<>"",K12<>""),IF(K12>J12,1,0),0)+IF(G12="Short",1,0)+IF(I12="No",1,0)+IF(IFERROR(INDEX(Classes!$C$6:$C$45,MATCH(A12,Classes!$B$6:$B$45,0)),"")<>B12,1,0))
A13: Adv 9A | B13: =IF(C13="","",LEFT(C13,FIND(" |",C13)-1)) | C13: Gr 9-12 | L5 Sextortion and Image Abuse | D13: 46364 | E13: 46349 | F13: =IF(OR(D13="",E13=""),"",D13-E13) | G13: =IF(F13="","",IF(F13>=Setup!$B$8,"OK","Short")) | H13: Yes | I13: No | J13: =IF(OR(A13="",C13=""),"",IFERROR(INDEX(Classes!$D$6:$D$45,MATCH(A13,Classes!$B$6:$B$45,0)),"")) | K13: 1 | L13: Yes | M13: =IF(OR(J13="",J13=0,K13=""),"",K13/J13) | N13: 1 | O13: 0 | P13: 0 | Q13: 0 | R13: =IF(C13="","",IF(A13="",1,0)+IF(J13="",1,0)+IF(AND(J13<>"",K13<>""),IF(K13>J13,1,0),0)+IF(G13="Short",1,0)+IF(I13="No",1,0)+IF(IFERROR(INDEX(Classes!$C$6:$C$45,MATCH(A13,Classes!$B$6:$B$45,0)),"")<>B13,1,0))
B14: =IF(C14="","",LEFT(C14,FIND(" |",C14)-1)) | F14: =IF(OR(D14="",E14=""),"",D14-E14) | G14: =IF(F14="","",IF(F14>=Setup!$B$8,"OK","Short")) | J14: =IF(OR(A14="",C14=""),"",IFERROR(INDEX(Classes!$D$6:$D$45,MATCH(A14,Classes!$B$6:$B$45,0)),"")) | M14: =IF(OR(J14="",J14=0,K14=""),"",K14/J14) | R14: =IF(C14="","",IF(A14="",1,0)+IF(J14="",1,0)+IF(AND(J14<>"",K14<>""),IF(K14>J14,1,0),0)+IF(G14="Short",1,0)+IF(I14="No",1,0)+IF(IFERROR(INDEX(Classes!$C$6:$C$45,MATCH(A14,Classes!$B$6:$B$45,0)),"")<>B14,1,0))
B15: =IF(C15="","",LEFT(C15,FIND(" |",C15)-1)) | F15: =IF(OR(D15="",E15=""),"",D15-E15) | G15: =IF(F15="","",IF(F15>=Setup!$B$8,"OK","Short")) | J15: =IF(OR(A15="",C15=""),"",IFERROR(INDEX(Classes!$D$6:$D$45,MATCH(A15,Classes!$B$6:$B$45,0)),"")) | M15: =IF(OR(J15="",J15=0,K15=""),"",K15/J15) | R15: =IF(C15="","",IF(A15="",1,0)+IF(J15="",1,0)+IF(AND(J15<>"",K15<>""),IF(K15>J15,1,0),0)+IF(G15="Short",1,0)+IF(I15="No",1,0)+IF(IFERROR(INDEX(Classes!$C$6:$C$45,MATCH(A15,Classes!$B$6:$B$45,0)),"")<>B15,1,0))
B16: =IF(C16="","",LEFT(C16,FIND(" |",C16)-1)) | F16: =IF(OR(D16="",E16=""),"",D16-E16) | G16: =IF(F16="","",IF(F16>=Setup!$B$8,"OK","Short")) | J16: =IF(OR(A16="",C16=""),"",IFERROR(INDEX(Classes!$D$6:$D$45,MATCH(A16,Classes!$B$6:$B$45,0)),"")) | M16: =IF(OR(J16="",J16=0,K16=""),"",K16/J16) | R16: =IF(C16="","",IF(A16="",1,0)+IF(J16="",1,0)+IF(AND(J16<>"",K16<>""),IF(K16>J16,1,0),0)+IF(G16="Short",1,0)+IF(I16="No",1,0)+IF(IFERROR(INDEX(Classes!$C$6:$C$45,MATCH(A16,Classes!$B$6:$B$45,0)),"")<>B16,1,0))
B17: =IF(C17="","",LEFT(C17,FIND(" |",C17)-1)) | F17: =IF(OR(D17="",E17=""),"",D17-E17) | G17: =IF(F17="","",IF(F17>=Setup!$B$8,"OK","Short")) | J17: =IF(OR(A17="",C17=""),"",IFERROR(INDEX(Classes!$D$6:$D$45,MATCH(A17,Classes!$B$6:$B$45,0)),"")) | M17: =IF(OR(J17="",J17=0,K17=""),"",K17/J17) | R17: =IF(C17="","",IF(A17="",1,0)+IF(J17="",1,0)+IF(AND(J17<>"",K17<>""),IF(K17>J17,1,0),0)+IF(G17="Short",1,0)+IF(I17="No",1,0)+IF(IFERROR(INDEX(Classes!$C$6:$C$45,MATCH(A17,Classes!$B$6:$B$45,0)),"")<>B17,1,0))
B18: =IF(C18="","",LEFT(C18,FIND(" |",C18)-1)) | F18: =IF(OR(D18="",E18=""),"",D18-E18) | G18: =IF(F18="","",IF(F18>=Setup!$B$8,"OK","Short")) | J18: =IF(OR(A18="",C18=""),"",IFERROR(INDEX(Classes!$D$6:$D$45,MATCH(A18,Classes!$B$6:$B$45,0)),"")) | M18: =IF(OR(J18="",J18=0,K18=""),"",K18/J18) | R18: =IF(C18="","",IF(A18="",1,0)+IF(J18="",1,0)+IF(AND(J18<>"",K18<>""),IF(K18>J18,1,0),0)+IF(G18="Short",1,0)+IF(I18="No",1,0)+IF(IFERROR(INDEX(Classes!$C$6:$C$45,MATCH(A18,Classes!$B$6:$B$45,0)),"")<>B18,1,0))
B19: =IF(C19="","",LEFT(C19,FIND(" |",C19)-1)) | F19: =IF(OR(D19="",E19=""),"",D19-E19) | G19: =IF(F19="","",IF(F19>=Setup!$B$8,"OK","Short")) | J19: =IF(OR(A19="",C19=""),"",IFERROR(INDEX(Classes!$D$6:$D$45,MATCH(A19,Classes!$B$6:$B$45,0)),"")) | M19: =IF(OR(J19="",J19=0,K19=""),"",K19/J19) | R19: =IF(C19="","",IF(A19="",1,0)+IF(J19="",1,0)+IF(AND(J19<>"",K19<>""),IF(K19>J19,1,0),0)+IF(G19="Short",1,0)+IF(I19="No",1,0)+IF(IFERROR(INDEX(Classes!$C$6:$C$45,MATCH(A19,Classes!$B$6:$B$45,0)),"")<>B19,1,0))
B20: =IF(C20="","",LEFT(C20,FIND(" |",C20)-1)) | F20: =IF(OR(D20="",E20=""),"",D20-E20) | G20: =IF(F20="","",IF(F20>=Setup!$B$8,"OK","Short")) | J20: =IF(OR(A20="",C20=""),"",IFERROR(INDEX(Classes!$D$6:$D$45,MATCH(A20,Classes!$B$6:$B$45,0)),"")) | M20: =IF(OR(J20="",J20=0,K20=""),"",K20/J20) | R20: =IF(C20="","",IF(A20="",1,0)+IF(J20="",1,0)+IF(AND(J20<>"",K20<>""),IF(K20>J20,1,0),0)+IF(G20="Short",1,0)+IF(I20="No",1,0)+IF(IFERROR(INDEX(Classes!$C$6:$C$45,MATCH(A20,Classes!$B$6:$B$45,0)),"")<>B20,1,0))
B21: =IF(C21="","",LEFT(C21,FIND(" |",C21)-1)) | F21: =IF(OR(D21="",E21=""),"",D21-E21) | G21: =IF(F21="","",IF(F21>=Setup!$B$8,"OK","Short")) | J21: =IF(OR(A21="",C21=""),"",IFERROR(INDEX(Classes!$D$6:$D$45,MATCH(A21,Classes!$B$6:$B$45,0)),"")) | M21: =IF(OR(J21="",J21=0,K21=""),"",K21/J21) | R21: =IF(C21="","",IF(A21="",1,0)+IF(J21="",1,0)+IF(AND(J21<>"",K21<>""),IF(K21>J21,1,0),0)+IF(G21="Short",1,0)+IF(I21="No",1,0)+IF(IFERROR(INDEX(Classes!$C$6:$C$45,MATCH(A21,Classes!$B$6:$B$45,0)),"")<>B21,1,0))
B22: =IF(C22="","",LEFT(C22,FIND(" |",C22)-1)) | F22: =IF(OR(D22="",E22=""),"",D22-E22) | G22: =IF(F22="","",IF(F22>=Setup!$B$8,"OK","Short")) | J22: =IF(OR(A22="",C22=""),"",IFERROR(INDEX(Classes!$D$6:$D$45,MATCH(A22,Classes!$B$6:$B$45,0)),"")) | M22: =IF(OR(J22="",J22=0,K22=""),"",K22/J22) | R22: =IF(C22="","",IF(A22="",1,0)+IF(J22="",1,0)+IF(AND(J22<>"",K22<>""),IF(K22>J22,1,0),0)+IF(G22="Short",1,0)+IF(I22="No",1,0)+IF(IFERROR(INDEX(Classes!$C$6:$C$45,MATCH(A22,Classes!$B$6:$B$45,0)),"")<>B22,1,0))
B23: =IF(C23="","",LEFT(C23,FIND(" |",C23)-1)) | F23: =IF(OR(D23="",E23=""),"",D23-E23) | G23: =IF(F23="","",IF(F23>=Setup!$B$8,"OK","Short")) | J23: =IF(OR(A23="",C23=""),"",IFERROR(INDEX(Classes!$D$6:$D$45,MATCH(A23,Classes!$B$6:$B$45,0)),"")) | M23: =IF(OR(J23="",J23=0,K23=""),"",K23/J23) | R23: =IF(C23="","",IF(A23="",1,0)+IF(J23="",1,0)+IF(AND(J23<>"",K23<>""),IF(K23>J23,1,0),0)+IF(G23="Short",1,0)+IF(I23="No",1,0)+IF(IFERROR(INDEX(Classes!$C$6:$C$45,MATCH(A23,Classes!$B$6:$B$45,0)),"")<>B23,1,0))
B24: =IF(C24="","",LEFT(C24,FIND(" |",C24)-1)) | F24: =IF(OR(D24="",E24=""),"",D24-E24) | G24: =IF(F24="","",IF(F24>=Setup!$B$8,"OK","Short")) | J24: =IF(OR(A24="",C24=""),"",IFERROR(INDEX(Classes!$D$6:$D$45,MATCH(A24,Classes!$B$6:$B$45,0)),"")) | M24: =IF(OR(J24="",J24=0,K24=""),"",K24/J24) | R24: =IF(C24="","",IF(A24="",1,0)+IF(J24="",1,0)+IF(AND(J24<>"",K24<>""),IF(K24>J24,1,0),0)+IF(G24="Short",1,0)+IF(I24="No",1,0)+IF(IFERROR(INDEX(Classes!$C$6:$C$45,MATCH(A24,Classes!$B$6:$B$45,0)),"")<>B24,1,0))
B25: =IF(C25="","",LEFT(C25,FIND(" |",C25)-1)) | F25: =IF(OR(D25="",E25=""),"",D25-E25) | G25: =IF(F25="","",IF(F25>=Setup!$B$8,"OK","Short")) | J25: =IF(OR(A25="",C25=""),"",IFERROR(INDEX(Classes!$D$6:$D$45,MATCH(A25,Classes!$B$6:$B$45,0)),"")) | M25: =IF(OR(J25="",J25=0,K25=""),"",K25/J25) | R25: =IF(C25="","",IF(A25="",1,0)+IF(J25="",1,0)+IF(AND(J25<>"",K25<>""),IF(K25>J25,1,0),0)+IF(G25="Short",1,0)+IF(I25="No",1,0)+IF(IFERROR(INDEX(Classes!$C$6:$C$45,MATCH(A25,Classes!$B$6:$B$45,0)),"")<>B25,1,0))
... B125: =IF(C125="","",LEFT(C125,FIND(" |",C125)-1)) | F125: =IF(OR(D125="",E125=""),"",D125-E125) | G125: =IF(F125="","",IF(F125>=Setup!$B$8,"OK","Short")) | J125: =IF(OR(A125="",C125=""),"",IFERROR(INDEX(Classes!$D$6:$D$45,MATCH(A125,Classes!$B$6:$B$45,0)),"")) | M125: =IF(OR(J125="",J125=0,K125=""),"",K125/J125) | R125: =IF(C125="","",IF(A125="",1,0)+IF(J125="",1,0)+IF(AND(J125<>"",K125<>""),IF(K125>J125,1,0),0)+IF(G125="Short",1,0)+IF(I125="No",1,0)+IF(IFERROR(INDEX(Classes!$C$6:$C$45,MATCH(A125,Classes!$B$6:$B$45,0)),"")<>B125,1,0))

Sheet Family
A1: Family engagement [EXAMPLE DATA: made up, not a real school]
A2: © 2026 Competence Collective. Lesson text and teaching materials CC BY-NC 4.0. The Hackles name, logos, characters and artwork are not covered by that license: print and share them unaltered for classroom and family use; any other use needs written permission. [VERIFY with counsel]
A3: Counts only. Families notified means letters or messages sent home. Reply slips returned are the optional Family Reply slips. Never record who replied.
A5: Class | B5: Band | C5: Families notified (count) | D5: Reply slips returned (count) | E5: Reply rate | F5: Family event attendees (count) | G5: Family previews held (count)
A6: =IF(Classes!B6="","",Classes!B6) | B6: =IF(Classes!B6="","",IF(Classes!C6="","",Classes!C6)) | C6: 22 | D6: 9 | E6: =IF(OR(A6="",C6="",C6=0,D6=""),"",D6/C6) | F6: 14 | G6: 2
A7: =IF(Classes!B7="","",Classes!B7) | B7: =IF(Classes!B7="","",IF(Classes!C7="","",Classes!C7)) | C7: 20 | D7: 7 | E7: =IF(OR(A7="",C7="",C7=0,D7=""),"",D7/C7) | F7: 11 | G7: 1
A8: =IF(Classes!B8="","",Classes!B8) | B8: =IF(Classes!B8="","",IF(Classes!C8="","",Classes!C8)) | C8: 24 | D8: 11 | E8: =IF(OR(A8="",C8="",C8=0,D8=""),"",D8/C8) | F8: 16 | G8: 3
A9: =IF(Classes!B9="","",Classes!B9) | B9: =IF(Classes!B9="","",IF(Classes!C9="","",Classes!C9)) | C9: 23 | D9: 8 | E9: =IF(OR(A9="",C9="",C9=0,D9=""),"",D9/C9) | F9: 12 | G9: 0
A10: =IF(Classes!B10="","",Classes!B10) | B10: =IF(Classes!B10="","",IF(Classes!C10="","",Classes!C10)) | C10: 27 | D10: 6 | E10: =IF(OR(A10="",C10="",C10=0,D10=""),"",D10/C10) | F10: 9 | G10: 1
A11: =IF(Classes!B11="","",Classes!B11) | B11: =IF(Classes!B11="","",IF(Classes!C11="","",Classes!C11)) | C11: 25 | D11: 5 | E11: =IF(OR(A11="",C11="",C11=0,D11=""),"",D11/C11) | F11: 8 | G11: 2
A12: =IF(Classes!B12="","",Classes!B12) | B12: =IF(Classes!B12="","",IF(Classes!C12="","",Classes!C12)) | C12: 8 | D12: 2 | E12: =IF(OR(A12="",C12="",C12=0,D12=""),"",D12/C12) | F12: 3 | G12: 0
A13: =IF(Classes!B13="","",Classes!B13) | B13: =IF(Classes!B13="","",IF(Classes!C13="","",Classes!C13)) | E13: =IF(OR(A13="",C13="",C13=0,D13=""),"",D13/C13)
A14: =IF(Classes!B14="","",Classes!B14) | B14: =IF(Classes!B14="","",IF(Classes!C14="","",Classes!C14)) | E14: =IF(OR(A14="",C14="",C14=0,D14=""),"",D14/C14)
A15: =IF(Classes!B15="","",Classes!B15) | B15: =IF(Classes!B15="","",IF(Classes!C15="","",Classes!C15)) | E15: =IF(OR(A15="",C15="",C15=0,D15=""),"",D15/C15)
A16: =IF(Classes!B16="","",Classes!B16) | B16: =IF(Classes!B16="","",IF(Classes!C16="","",Classes!C16)) | E16: =IF(OR(A16="",C16="",C16=0,D16=""),"",D16/C16)
A17: =IF(Classes!B17="","",Classes!B17) | B17: =IF(Classes!B17="","",IF(Classes!C17="","",Classes!C17)) | E17: =IF(OR(A17="",C17="",C17=0,D17=""),"",D17/C17)
A18: =IF(Classes!B18="","",Classes!B18) | B18: =IF(Classes!B18="","",IF(Classes!C18="","",Classes!C18)) | E18: =IF(OR(A18="",C18="",C18=0,D18=""),"",D18/C18)
A19: =IF(Classes!B19="","",Classes!B19) | B19: =IF(Classes!B19="","",IF(Classes!C19="","",Classes!C19)) | E19: =IF(OR(A19="",C19="",C19=0,D19=""),"",D19/C19)
A20: =IF(Classes!B20="","",Classes!B20) | B20: =IF(Classes!B20="","",IF(Classes!C20="","",Classes!C20)) | E20: =IF(OR(A20="",C20="",C20=0,D20=""),"",D20/C20)
A21: =IF(Classes!B21="","",Classes!B21) | B21: =IF(Classes!B21="","",IF(Classes!C21="","",Classes!C21)) | E21: =IF(OR(A21="",C21="",C21=0,D21=""),"",D21/C21)
A22: =IF(Classes!B22="","",Classes!B22) | B22: =IF(Classes!B22="","",IF(Classes!C22="","",Classes!C22)) | E22: =IF(OR(A22="",C22="",C22=0,D22=""),"",D22/C22)
A23: =IF(Classes!B23="","",Classes!B23) | B23: =IF(Classes!B23="","",IF(Classes!C23="","",Classes!C23)) | E23: =IF(OR(A23="",C23="",C23=0,D23=""),"",D23/C23)
A24: =IF(Classes!B24="","",Classes!B24) | B24: =IF(Classes!B24="","",IF(Classes!C24="","",Classes!C24)) | E24: =IF(OR(A24="",C24="",C24=0,D24=""),"",D24/C24)
... A45: =IF(Classes!B45="","",Classes!B45) | B45: =IF(Classes!B45="","",IF(Classes!C45="","",Classes!C45)) | E45: =IF(OR(A45="",C45="",C45=0,D45=""),"",D45/C45)

Sheet Summary
A1: School summary by grade band [EXAMPLE DATA: made up, not a real school]
A2: © 2026 Competence Collective. Lesson text and teaching materials CC BY-NC 4.0. The Hackles name, logos, characters and artwork are not covered by that license: print and share them unaltered for classroom and family use; any other use needs written permission. [VERIFY with counsel]
A3: Follows the Assessment Pack's administrator impact summary. Percentages for groups smaller than the suppression threshold on Setup show as n<10 (or your number).
A4: Measure | B4: Gr K-2 | C4: Gr 3-5 | D4: Gr 6-8 | E4: Gr 9-12 | F4: All bands
A5: 1. Reach and lessons
A6: Classes or groups | B6: =COUNTIF(Classes!$C$6:$C$45,B$4) | C6: =COUNTIF(Classes!$C$6:$C$45,C$4) | D6: =COUNTIF(Classes!$C$6:$C$45,D$4) | E6: =COUNTIF(Classes!$C$6:$C$45,E$4) | F6: =SUM(B6:E6)
A7: Students enrolled | B7: =SUMIF(Classes!$C$6:$C$45,B$4,Classes!$D$6:$D$45) | C7: =SUMIF(Classes!$C$6:$C$45,C$4,Classes!$D$6:$D$45) | D7: =SUMIF(Classes!$C$6:$C$45,D$4,Classes!$D$6:$D$45) | E7: =SUMIF(Classes!$C$6:$C$45,E$4,Classes!$D$6:$D$45) | F7: =SUM(B7:E7)
A8: Core lessons delivered, average per class (of 10) | B8: =IF(B6=0,"",SUMIF(Lessons!$B$6:$B$45,B$4,Lessons!$Q$6:$Q$45)/B6) | C8: =IF(C6=0,"",SUMIF(Lessons!$B$6:$B$45,C$4,Lessons!$Q$6:$Q$45)/C6) | D8: =IF(D6=0,"",SUMIF(Lessons!$B$6:$B$45,D$4,Lessons!$Q$6:$Q$45)/D6) | E8: =IF(E6=0,"",SUMIF(Lessons!$B$6:$B$45,E$4,Lessons!$Q$6:$Q$45)/E6) | F8: =IF(F6=0,"",SUM(Lessons!$Q$6:$Q$45)/F6)
A9: Core lesson completion | B9: =IF(B6=0,"",SUMIF(Lessons!$B$6:$B$45,B$4,Lessons!$Q$6:$Q$45)/(10*B6)) | C9: =IF(C6=0,"",SUMIF(Lessons!$B$6:$B$45,C$4,Lessons!$Q$6:$Q$45)/(10*C6)) | D9: =IF(D6=0,"",SUMIF(Lessons!$B$6:$B$45,D$4,Lessons!$Q$6:$Q$45)/(10*D6)) | E9: =IF(E6=0,"",SUMIF(Lessons!$B$6:$B$45,E$4,Lessons!$Q$6:$Q$45)/(10*E6)) | F9: =IF(F6=0,"",SUM(Lessons!$Q$6:$Q$45)/(10*F6))
A10: Plus lessons delivered (total, grades 6-12) | B10: =SUMIF(Lessons!$B$6:$B$45,B$4,Lessons!$T$6:$T$45) | C10: =SUMIF(Lessons!$B$6:$B$45,C$4,Lessons!$T$6:$T$45) | D10: =SUMIF(Lessons!$B$6:$B$45,D$4,Lessons!$T$6:$T$45) | E10: =SUMIF(Lessons!$B$6:$B$45,E$4,Lessons!$T$6:$T$45) | F10: =SUM(B10:E10)
A11: 2. Help Ladder practice
A12: Help Ladder practice sessions (total) | B12: =SUMIF(HelpLadder!$B$6:$B$45,B$4,HelpLadder!$D$6:$D$45) | C12: =SUMIF(HelpLadder!$B$6:$B$45,C$4,HelpLadder!$D$6:$D$45) | D12: =SUMIF(HelpLadder!$B$6:$B$45,D$4,HelpLadder!$D$6:$D$45) | E12: =SUMIF(HelpLadder!$B$6:$B$45,E$4,HelpLadder!$D$6:$D$45) | F12: =SUM(B12:E12)
A13: Students who practiced the first sentence aloud (% of enrolled) | B13: =IF(B7=0,"",SUMIF(HelpLadder!$B$6:$B$45,B$4,HelpLadder!$E$6:$E$45)/B7) | C13: =IF(C7=0,"",SUMIF(HelpLadder!$B$6:$B$45,C$4,HelpLadder!$E$6:$E$45)/C7) | D13: =IF(D7=0,"",SUMIF(HelpLadder!$B$6:$B$45,D$4,HelpLadder!$E$6:$E$45)/D7) | E13: =IF(E7=0,"",SUMIF(HelpLadder!$B$6:$B$45,E$4,HelpLadder!$E$6:$E$45)/E7) | F13: =IF(F7=0,"",SUM(HelpLadder!$E$6:$E$45)/F7)
A14: 3. Tell-Readiness (core items, class totals)
A15: Pre survey: students who answered | B15: =SUMIF(Surveys!$B$6:$B$45,B$4,Surveys!$D$6:$D$45) | C15: =SUMIF(Surveys!$B$6:$B$45,C$4,Surveys!$D$6:$D$45) | D15: =SUMIF(Surveys!$B$6:$B$45,D$4,Surveys!$D$6:$D$45) | E15: =SUMIF(Surveys!$B$6:$B$45,E$4,Surveys!$D$6:$D$45) | F15: =SUM(B15:E15)
A16: Post survey: students who answered | B16: =SUMIF(Surveys!$B$6:$B$45,B$4,Surveys!$I$6:$I$45) | C16: =SUMIF(Surveys!$B$6:$B$45,C$4,Surveys!$I$6:$I$45) | D16: =SUMIF(Surveys!$B$6:$B$45,D$4,Surveys!$I$6:$I$45) | E16: =SUMIF(Surveys!$B$6:$B$45,E$4,Surveys!$I$6:$I$45) | F16: =SUM(B16:E16)
A17: Tell-Readiness before | B17: =IF(B15=0,"",IF(B15<Setup!$B$6,"n<"&Setup!$B$6,(SUMIF(Surveys!$B$6:$B$45,B$4,Surveys!$E$6:$E$45)+SUMIF(Surveys!$B$6:$B$45,B$4,Surveys!$F$6:$F$45)+SUMIF(Surveys!$B$6:$B$45,B$4,Surveys!$G$6:$G$45))/(3*B15))) | C17: =IF(C15=0,"",IF(C15<Setup!$B$6,"n<"&Setup!$B$6,(SUMIF(Surveys!$B$6:$B$45,C$4,Surveys!$E$6:$E$45)+SUMIF(Surveys!$B$6:$B$45,C$4,Surveys!$F$6:$F$45)+SUMIF(Surveys!$B$6:$B$45,C$4,Surveys!$G$6:$G$45))/(3*C15))) | D17: =IF(D15=0,"",IF(D15<Setup!$B$6,"n<"&Setup!$B$6,(SUMIF(Surveys!$B$6:$B$45,D$4,Surveys!$E$6:$E$45)+SUMIF(Surveys!$B$6:$B$45,D$4,Surveys!$F$6:$F$45)+SUMIF(Surveys!$B$6:$B$45,D$4,Surveys!$G$6:$G$45))/(3*D15))) | E17: =IF(E15=0,"",IF(E15<Setup!$B$6,"n<"&Setup!$B$6,(SUMIF(Surveys!$B$6:$B$45,E$4,Surveys!$E$6:$E$45)+SUMIF(Surveys!$B$6:$B$45,E$4,Surveys!$F$6:$F$45)+SUMIF(Surveys!$B$6:$B$45,E$4,Surveys!$G$6:$G$45))/(3*E15))) | F17: =IF(F15=0,"",IF(F15<Setup!$B$6,"n<"&Setup!$B$6,(SUM(Surveys!$E$6:$E$45)+SUM(Surveys!$F$6:$F$45)+SUM(Surveys!$G$6:$G$45))/(3*F15)))
A18: Tell-Readiness after | B18: =IF(B16=0,"",IF(B16<Setup!$B$6,"n<"&Setup!$B$6,(SUMIF(Surveys!$B$6:$B$45,B$4,Surveys!$J$6:$J$45)+SUMIF(Surveys!$B$6:$B$45,B$4,Surveys!$K$6:$K$45)+SUMIF(Surveys!$B$6:$B$45,B$4,Surveys!$L$6:$L$45))/(3*B16))) | C18: =IF(C16=0,"",IF(C16<Setup!$B$6,"n<"&Setup!$B$6,(SUMIF(Surveys!$B$6:$B$45,C$4,Surveys!$J$6:$J$45)+SUMIF(Surveys!$B$6:$B$45,C$4,Surveys!$K$6:$K$45)+SUMIF(Surveys!$B$6:$B$45,C$4,Surveys!$L$6:$L$45))/(3*C16))) | D18: =IF(D16=0,"",IF(D16<Setup!$B$6,"n<"&Setup!$B$6,(SUMIF(Surveys!$B$6:$B$45,D$4,Surveys!$J$6:$J$45)+SUMIF(Surveys!$B$6:$B$45,D$4,Surveys!$K$6:$K$45)+SUMIF(Surveys!$B$6:$B$45,D$4,Surveys!$L$6:$L$45))/(3*D16))) | E18: =IF(E16=0,"",IF(E16<Setup!$B$6,"n<"&Setup!$B$6,(SUMIF(Surveys!$B$6:$B$45,E$4,Surveys!$J$6:$J$45)+SUMIF(Surveys!$B$6:$B$45,E$4,Surveys!$K$6:$K$45)+SUMIF(Surveys!$B$6:$B$45,E$4,Surveys!$L$6:$L$45))/(3*E16))) | F18: =IF(F16=0,"",IF(F16<Setup!$B$6,"n<"&Setup!$B$6,(SUM(Surveys!$J$6:$J$45)+SUM(Surveys!$K$6:$K$45)+SUM(Surveys!$L$6:$L$45))/(3*F16)))
A19: Change (percentage points) | B19: =IF(AND(ISNUMBER(B17),ISNUMBER(B18)),(B18-B17)*100,"") | C19: =IF(AND(ISNUMBER(C17),ISNUMBER(C18)),(C18-C17)*100,"") | D19: =IF(AND(ISNUMBER(D17),ISNUMBER(D18)),(D18-D17)*100,"") | E19: =IF(AND(ISNUMBER(E17),ISNUMBER(E18)),(E18-E17)*100,"") | F19: =IF(AND(ISNUMBER(F17),ISNUMBER(F18)),(F18-F17)*100,"")
A20: Confident to tell, before | B20: =IF(B15=0,"",IF(B15<Setup!$B$6,"n<"&Setup!$B$6,SUMIF(Surveys!$B$6:$B$45,B$4,Surveys!$H$6:$H$45)/B15)) | C20: =IF(C15=0,"",IF(C15<Setup!$B$6,"n<"&Setup!$B$6,SUMIF(Surveys!$B$6:$B$45,C$4,Surveys!$H$6:$H$45)/C15)) | D20: =IF(D15=0,"",IF(D15<Setup!$B$6,"n<"&Setup!$B$6,SUMIF(Surveys!$B$6:$B$45,D$4,Surveys!$H$6:$H$45)/D15)) | E20: =IF(E15=0,"",IF(E15<Setup!$B$6,"n<"&Setup!$B$6,SUMIF(Surveys!$B$6:$B$45,E$4,Surveys!$H$6:$H$45)/E15)) | F20: =IF(F15=0,"",IF(F15<Setup!$B$6,"n<"&Setup!$B$6,SUM(Surveys!$H$6:$H$45)/F15))
A21: Confident to tell, after | B21: =IF(B16=0,"",IF(B16<Setup!$B$6,"n<"&Setup!$B$6,SUMIF(Surveys!$B$6:$B$45,B$4,Surveys!$M$6:$M$45)/B16)) | C21: =IF(C16=0,"",IF(C16<Setup!$B$6,"n<"&Setup!$B$6,SUMIF(Surveys!$B$6:$B$45,C$4,Surveys!$M$6:$M$45)/C16)) | D21: =IF(D16=0,"",IF(D16<Setup!$B$6,"n<"&Setup!$B$6,SUMIF(Surveys!$B$6:$B$45,D$4,Surveys!$M$6:$M$45)/D16)) | E21: =IF(E16=0,"",IF(E16<Setup!$B$6,"n<"&Setup!$B$6,SUMIF(Surveys!$B$6:$B$45,E$4,Surveys!$M$6:$M$45)/E16)) | F21: =IF(F16=0,"",IF(F16<Setup!$B$6,"n<"&Setup!$B$6,SUM(Surveys!$M$6:$M$45)/F16))
A22: Matched pre/post pairs | B22: =SUMIF(Surveys!$B$6:$B$45,B$4,Surveys!$N$6:$N$45) | C22: =SUMIF(Surveys!$B$6:$B$45,C$4,Surveys!$N$6:$N$45) | D22: =SUMIF(Surveys!$B$6:$B$45,D$4,Surveys!$N$6:$N$45) | E22: =SUMIF(Surveys!$B$6:$B$45,E$4,Surveys!$N$6:$N$45) | F22: =SUM(B22:E22)
A23: 4. Sensitive lessons and support (counts)
A24: Sensitive lessons taught (class sessions) | B24: =COUNTIF(Sensitive!$B$6:$B$125,B$4) | C24: =COUNTIF(Sensitive!$B$6:$B$125,C$4) | D24: =COUNTIF(Sensitive!$B$6:$B$125,D$4) | E24: =COUNTIF(Sensitive!$B$6:$B$125,E$4) | F24: =SUM(B24:E24)
A25: Opt-out requests (total) | B25: =SUMIFS(Sensitive!$K$6:$K$125,Sensitive!$B$6:$B$125,B$4) | C25: =SUMIFS(Sensitive!$K$6:$K$125,Sensitive!$B$6:$B$125,C$4) | D25: =SUMIFS(Sensitive!$K$6:$K$125,Sensitive!$B$6:$B$125,D$4) | E25: =SUMIFS(Sensitive!$K$6:$K$125,Sensitive!$B$6:$B$125,E$4) | F25: =SUM(B25:E25)
A26: Opt-out requests per student in those lessons | B26: =IF(SUMIFS(Sensitive!$J$6:$J$125,Sensitive!$B$6:$B$125,B$4)=0,"",B25/SUMIFS(Sensitive!$J$6:$J$125,Sensitive!$B$6:$B$125,B$4)) | C26: =IF(SUMIFS(Sensitive!$J$6:$J$125,Sensitive!$B$6:$B$125,C$4)=0,"",C25/SUMIFS(Sensitive!$J$6:$J$125,Sensitive!$B$6:$B$125,C$4)) | D26: =IF(SUMIFS(Sensitive!$J$6:$J$125,Sensitive!$B$6:$B$125,D$4)=0,"",D25/SUMIFS(Sensitive!$J$6:$J$125,Sensitive!$B$6:$B$125,D$4)) | E26: =IF(SUMIFS(Sensitive!$J$6:$J$125,Sensitive!$B$6:$B$125,E$4)=0,"",E25/SUMIFS(Sensitive!$J$6:$J$125,Sensitive!$B$6:$B$125,E$4)) | F26: =IF(SUM(Sensitive!$J$6:$J$125)=0,"",F25/SUM(Sensitive!$J$6:$J$125))
A27: Sessions with an alternate activity offered | B27: =COUNTIFS(Sensitive!$B$6:$B$125,B$4,Sensitive!$L$6:$L$125,"Yes") | C27: =COUNTIFS(Sensitive!$B$6:$B$125,C$4,Sensitive!$L$6:$L$125,"Yes") | D27: =COUNTIFS(Sensitive!$B$6:$B$125,D$4,Sensitive!$L$6:$L$125,"Yes") | E27: =COUNTIFS(Sensitive!$B$6:$B$125,E$4,Sensitive!$L$6:$L$125,"Yes") | F27: =SUM(B27:E27)
A28: Sessions with at least the minimum family notice | B28: =COUNTIFS(Sensitive!$B$6:$B$125,B$4,Sensitive!$G$6:$G$125,"OK") | C28: =COUNTIFS(Sensitive!$B$6:$B$125,C$4,Sensitive!$G$6:$G$125,"OK") | D28: =COUNTIFS(Sensitive!$B$6:$B$125,D$4,Sensitive!$G$6:$G$125,"OK") | E28: =COUNTIFS(Sensitive!$B$6:$B$125,E$4,Sensitive!$G$6:$G$125,"OK") | F28: =SUM(B28:E28)
A29: Sessions with a counselor available | B29: =COUNTIFS(Sensitive!$B$6:$B$125,B$4,Sensitive!$I$6:$I$125,"Yes") | C29: =COUNTIFS(Sensitive!$B$6:$B$125,C$4,Sensitive!$I$6:$I$125,"Yes") | D29: =COUNTIFS(Sensitive!$B$6:$B$125,D$4,Sensitive!$I$6:$I$125,"Yes") | E29: =COUNTIFS(Sensitive!$B$6:$B$125,E$4,Sensitive!$I$6:$I$125,"Yes") | F29: =SUM(B29:E29)
A30: Students who asked to talk (count) | B30: =SUMIFS(Sensitive!$N$6:$N$125,Sensitive!$B$6:$B$125,B$4) | C30: =SUMIFS(Sensitive!$N$6:$N$125,Sensitive!$B$6:$B$125,C$4) | D30: =SUMIFS(Sensitive!$N$6:$N$125,Sensitive!$B$6:$B$125,D$4) | E30: =SUMIFS(Sensitive!$N$6:$N$125,Sensitive!$B$6:$B$125,E$4) | F30: =SUM(B30:E30)
A31: Concerns or disclosures raised (count) | B31: =SUMIFS(Sensitive!$O$6:$O$125,Sensitive!$B$6:$B$125,B$4) | C31: =SUMIFS(Sensitive!$O$6:$O$125,Sensitive!$B$6:$B$125,C$4) | D31: =SUMIFS(Sensitive!$O$6:$O$125,Sensitive!$B$6:$B$125,D$4) | E31: =SUMIFS(Sensitive!$O$6:$O$125,Sensitive!$B$6:$B$125,E$4) | F31: =SUM(B31:E31)
A32: Referred to counselor (count) | B32: =SUMIFS(Sensitive!$P$6:$P$125,Sensitive!$B$6:$B$125,B$4) | C32: =SUMIFS(Sensitive!$P$6:$P$125,Sensitive!$B$6:$B$125,C$4) | D32: =SUMIFS(Sensitive!$P$6:$P$125,Sensitive!$B$6:$B$125,D$4) | E32: =SUMIFS(Sensitive!$P$6:$P$125,Sensitive!$B$6:$B$125,E$4) | F32: =SUM(B32:E32)
A33: Reports made as required (count) | B33: =SUMIFS(Sensitive!$Q$6:$Q$125,Sensitive!$B$6:$B$125,B$4) | C33: =SUMIFS(Sensitive!$Q$6:$Q$125,Sensitive!$B$6:$B$125,C$4) | D33: =SUMIFS(Sensitive!$Q$6:$Q$125,Sensitive!$B$6:$B$125,D$4) | E33: =SUMIFS(Sensitive!$Q$6:$Q$125,Sensitive!$B$6:$B$125,E$4) | F33: =SUM(B33:E33)
A34: 5. Families
A35: Families notified | B35: =SUMIF(Family!$B$6:$B$45,B$4,Family!$C$6:$C$45) | C35: =SUMIF(Family!$B$6:$B$45,C$4,Family!$C$6:$C$45) | D35: =SUMIF(Family!$B$6:$B$45,D$4,Family!$C$6:$C$45) | E35: =SUMIF(Family!$B$6:$B$45,E$4,Family!$C$6:$C$45) | F35: =SUM(B35:E35)
A36: Reply slips returned | B36: =SUMIF(Family!$B$6:$B$45,B$4,Family!$D$6:$D$45) | C36: =SUMIF(Family!$B$6:$B$45,C$4,Family!$D$6:$D$45) | D36: =SUMIF(Family!$B$6:$B$45,D$4,Family!$D$6:$D$45) | E36: =SUMIF(Family!$B$6:$B$45,E$4,Family!$D$6:$D$45) | F36: =SUM(B36:E36)
A37: Reply rate | B37: =IF(B35=0,"",B36/B35) | C37: =IF(C35=0,"",C36/C35) | D37: =IF(D35=0,"",D36/D35) | E37: =IF(E35=0,"",E36/E35) | F37: =IF(F35=0,"",F36/F35)
A38: Family event attendees | B38: =SUMIF(Family!$B$6:$B$45,B$4,Family!$F$6:$F$45) | C38: =SUMIF(Family!$B$6:$B$45,C$4,Family!$F$6:$F$45) | D38: =SUMIF(Family!$B$6:$B$45,D$4,Family!$F$6:$F$45) | E38: =SUMIF(Family!$B$6:$B$45,E$4,Family!$F$6:$F$45) | F38: =SUM(B38:E38)
A39: Family previews held | B39: =SUMIF(Family!$B$6:$B$45,B$4,Family!$G$6:$G$45) | C39: =SUMIF(Family!$B$6:$B$45,C$4,Family!$G$6:$G$45) | D39: =SUMIF(Family!$B$6:$B$45,D$4,Family!$G$6:$G$45) | E39: =SUMIF(Family!$B$6:$B$45,E$4,Family!$G$6:$G$45) | F39: =SUM(B39:E39)
